Workbook

Sheet latency
A1: size_bytes | B1: n_samples | D1: term | E1: mean_us | F1: p50_us | G1: p99_us
A2: 1024 | B2: 10000 | D2: Total | E2: 786.8 | F2: 732.7 | G2: 1127.9
C3: RaftLeader | D3: LHandler | E3: 5.1 | F3: 3.3 | G3: 27.5
D4: LPersist | E4: 131.8 | F4: 120.1 | G4: 250.2
C5: Network | D5: AENet | E5: 77.6 | F5: 61.8 | G5: 199
C6: Follwer Repliction | D6: FHandler | E6: 5.5 | F6: 3.6 | G6: 34.6
D7: ReplNet | E7: 189.4 | F7: 171.5 | G7: 349.9
D8: StorageIO | E8: 148.3 | F8: 146.4 | G8: 207.3
C9: RaftLeader | D9: QuorumWait | E9: 207.4 | F9: 202.3 | G9: 382.4
C12: ApplySM | D12: residual | E12: 21.6 | F12: 20 | G12: 66.2
A13: 2048 | B13: 10000 | D13: Total | E13: 738.9 | F13: 709 | G13: 1104
C14: RaftLeader | D14: LHandler | E14: 6.9 | F14: 3.1 | G14: 29.3
D15: LPersist | E15: 115.5 | F15: 102.4 | G15: 235.7
C16: Network | D16: AENet | E16: 76.4 | F16: 60.4 | G16: 196.9
C17: Follwer Repliction | D17: FHandler | E17: 5.7 | F17: 3.5 | G17: 34.7
D18: ReplNet | E18: 163.8 | F18: 155.8 | G18: 319.5
D19: StorageIO | E19: 143 | F19: 139.8 | G19: 205.3
C20: RaftLeader | D20: QuorumWait | E20: 200.2 | F20: 198.9 | G20: 356.6
D21: Mutex | E21: 2.2 | F21: 0.7 | G21: 13.5
D22: CommitWait | E22: 532.1 | F22: 512.3 | G22: 800.6
C23: ApplySM | D23: residual | E23: 27.3 | F23: 19.9 | G23: 56.3
A24: 4096 | B24: 10000 | D24: Total | E24: 835.1 | F24: 759.2 | G24: 1164.2
C25: RaftLeader | D25: LHandler | E25: 10.4 | F25: 8.1 | G25: 28.7
D26: LPersist | E26: 150.9 | F26: 134.7 | G26: 272.6
C27: Network | D27: AENet | E27: 89.2 | F27: 65.4 | G27: 206.2
C28: Follwer Repliction | D28: FHandler | E28: 6.1 | F28: 3.6 | G28: 34.4
D29: ReplNet | E29: 184.3 | F29: 170.5 | G29: 333.8
D30: StorageIO | E30: 159.9 | F30: 156.7 | G30: 231.9
C31: RaftLeader | D31: QuorumWait | E31: 205.7 | F31: 197.2 | G31: 362.1
D32: Mutex | E32: 1.4 | F32: 0.8 | G32: 11.1
D33: CommitWait | E33: 584.5 | F33: 521 | G33: 794.9
C34: ApplySM | D34: residual | E34: 28.5 | F34: 20.5 | G34: 55.2
A35: 8192 | B35: 10000 | D35: Total | E35: 786.6 | F35: 756.6 | G35: 1119.2
C36: RaftLeader | D36: LHandler | E36: 12.3 | F36: 9.4 | G36: 38.4
D37: LPersist | E37: 132.9 | F37: 128.3 | G37: 216.5
C38: Network | D38: AENet | E38: 108.1 | F38: 71.1 | G38: 209.6
C39: Follwer Repliction | D39: FHandler | E39: 6.2 | F39: 4 | G39: 37.5
D40: ReplNet | E40: 142.9 | F40: 133.7 | G40: 314.8
D41: StorageIO | E41: 135.6 | F41: 132.3 | G41: 213.5
C42: RaftLeader | D42: QuorumWait | E42: 201 | F42: 205.3 | G42: 362
...

Sheet chart_data
A1: size_bytes별 구간 누적 지연시간 (us)
A3: Mean (us)
A4: size_bytes | B4: RaftLeader | C4: Network | D4: FollowerReplication | E4: ApplySM | F4: Total (구간 합) | G4: Total (원본 측정) | I4: base(도우미) | J4: metric_col
A5: 1KB | B5: =SUM(OFFSET(latency!$A$1,$I5+1,$J5),OFFSET(latency!$A$1,$I5+2,$J5),OFFSET(latency!$A$1,$I5+7,$J5),OFFSET(latency!$A$1,$I5+8,$J5),OFFSET(latency!$A$1,$I5+9,$J5)) -> 344.3 | C5: =OFFSET(latency!$A$1,$I5+3,$J5) -> 77.6 | D5: =SUM(OFFSET(latency!$A$1,$I5+4,$J5),OFFSET(latency!$A$1,$I5+5,$J5),OFFSET(latency!$A$1,$I5+6,$J5)) -> 343.2 | E5: =OFFSET(latency!$A$1,$I5+10,$J5) -> 21.6 | F5: =SUM(B5:E5) -> 786.7 | G5: =OFFSET(latency!$A$1,$I5,$J5) -> 786.8 | I5: 1 | J5: 4
A6: 2KB | B6: =SUM(OFFSET(latency!$A$1,$I6+1,$J6),OFFSET(latency!$A$1,$I6+2,$J6),OFFSET(latency!$A$1,$I6+7,$J6),OFFSET(latency!$A$1,$I6+8,$J6),OFFSET(latency!$A$1,$I6+9,$J6)) -> 856.9 | C6: =OFFSET(latency!$A$1,$I6+3,$J6) -> 76.4 | D6: =SUM(OFFSET(latency!$A$1,$I6+4,$J6),OFFSET(latency!$A$1,$I6+5,$J6),OFFSET(latency!$A$1,$I6+6,$J6)) -> 312.5 | E6: =OFFSET(latency!$A$1,$I6+10,$J6) -> 27.3 | F6: =SUM(B6:E6) -> 1273.1 | G6: =OFFSET(latency!$A$1,$I6,$J6) -> 738.9 | I6: 12 | J6: 4
A7: 4KB | B7: =SUM(OFFSET(latency!$A$1,$I7+1,$J7),OFFSET(latency!$A$1,$I7+2,$J7),OFFSET(latency!$A$1,$I7+7,$J7),OFFSET(latency!$A$1,$I7+8,$J7),OFFSET(latency!$A$1,$I7+9,$J7)) -> 952.9 | C7: =OFFSET(latency!$A$1,$I7+3,$J7) -> 89.2 | D7: =SUM(OFFSET(latency!$A$1,$I7+4,$J7),OFFSET(latency!$A$1,$I7+5,$J7),OFFSET(latency!$A$1,$I7+6,$J7)) -> 350.3 | E7: =OFFSET(latency!$A$1,$I7+10,$J7) -> 28.5 | F7: =SUM(B7:E7) -> 1420.9 | G7: =OFFSET(latency!$A$1,$I7,$J7) -> 835.1 | I7: 23 | J7: 4
A8: 8KB | B8: =SUM(OFFSET(latency!$A$1,$I8+1,$J8),OFFSET(latency!$A$1,$I8+2,$J8),OFFSET(latency!$A$1,$I8+7,$J8),OFFSET(latency!$A$1,$I8+8,$J8),OFFSET(latency!$A$1,$I8+9,$J8)) -> 888.6 | C8: =OFFSET(latency!$A$1,$I8+3,$J8) -> 108.1 | D8: =SUM(OFFSET(latency!$A$1,$I8+4,$J8),OFFSET(latency!$A$1,$I8+5,$J8),OFFSET(latency!$A$1,$I8+6,$J8)) -> 284.7 | E8: =OFFSET(latency!$A$1,$I8+10,$J8) -> 47.5 | F8: =SUM(B8:E8) -> 1328.9 | G8: =OFFSET(latency!$A$1,$I8,$J8) -> 786.6 | I8: 34 | J8: 4
A9: 16KB | B9: =SUM(OFFSET(latency!$A$1,$I9+1,$J9),OFFSET(latency!$A$1,$I9+2,$J9),OFFSET(latency!$A$1,$I9+7,$J9),OFFSET(latency!$A$1,$I9+8,$J9),OFFSET(latency!$A$1,$I9+9,$J9)) -> 1063.3 | C9: =OFFSET(latency!$A$1,$I9+3,$J9) -> 111.3 | D9: =SUM(OFFSET(latency!$A$1,$I9+4,$J9),OFFSET(latency!$A$1,$I9+5,$J9),OFFSET(latency!$A$1,$I9+6,$J9)) -> 384.4 | E9: =OFFSET(latency!$A$1,$I9+10,$J9) -> 71.5 | F9: =SUM(B9:E9) -> 1630.5 | G9: =OFFSET(latency!$A$1,$I9,$J9) -> 982.6 | I9: 45 | J9: 4
A10: 32KB | B10: =SUM(OFFSET(latency!$A$1,$I10+1,$J10),OFFSET(latency!$A$1,$I10+2,$J10),OFFSET(latency!$A$1,$I10+7,$J10),OFFSET(latency!$A$1,$I10+8,$J10),OFFSET(latency!$A$1,$I10+9,$J10)) -> 1127.1 | C10: =OFFSET(latency!$A$1,$I10+3,$J10) -> 138.5 | D10: =SUM(OFFSET(latency!$A$1,$I10+4,$J10),OFFSET(latency!$A$1,$I10+5,$J10),OFFSET(latency!$A$1,$I10+6,$J10)) -> 378.9 | E10: =OFFSET(latency!$A$1,$I10+10,$J10) -> 111.8 | F10: =SUM(B10:E10) -> 1756.3 | G10: =OFFSET(latency!$A$1,$I10,$J10) -> 1079.5 | I10: 56 | J10: 4
A11: 64KB | B11: =SUM(OFFSET(latency!$A$1,$I11+1,$J11),OFFSET(latency!$A$1,$I11+2,$J11),OFFSET(latency!$A$1,$I11+7,$J11),OFFSET(latency!$A$1,$I11+8,$J11),OFFSET(latency!$A$1,$I11+9,$J11)) -> 1382.8 | C11: =OFFSET(latency!$A$1,$I11+3,$J11) -> 158.9 | D11: =SUM(OFFSET(latency!$A$1,$I11+4,$J11),OFFSET(latency!$A$1,$I11+5,$J11),OFFSET(latency!$A$1,$I11+6,$J11)) -> 504.8 | E11: =OFFSET(latency!$A$1,$I11+10,$J11) -> 190.7 | F11: =SUM(B11:E11) -> 2237.2 | G11: =OFFSET(latency!$A$1,$I11,$J11) -> 1417.8 | I11: 67 | J11: 4
A12: 128KB | B12: =SUM(OFFSET(latency!$A$1,$I12+1,$J12),OFFSET(latency!$A$1,$I12+2,$J12),OFFSET(latency!$A$1,$I12+7,$J12),OFFSET(latency!$A$1,$I12+8,$J12),OFFSET(latency!$A$1,$I12+9,$J12)) -> 1765.9 | C12: =OFFSET(latency!$A$1,$I12+3,$J12) -> 176.8 | D12: =SUM(OFFSET(latency!$A$1,$I12+4,$J12),OFFSET(latency!$A$1,$I12+5,$J12),OFFSET(latency!$A$1,$I12+6,$J12)) -> 701.6 | E12: =OFFSET(latency!$A$1,$I12+10,$J12) -> 294 | F12: =SUM(B12:E12) -> 2938.3 | G12: =OFFSET(latency!$A$1,$I12,$J12) -> 1914.9 | I12: 78 | J12: 4
A14: p50 (us)
A15: size_bytes | B15: RaftLeader | C15: Network | D15: FollowerReplication | E15: ApplySM | F15: Total (구간 합) | G15: Total (원본 측정) | I15: base(도우미) | J15: metric_col
A16: 1KB | B16: =SUM(OFFSET(latency!$A$1,$I16+1,$J16),OFFSET(latency!$A$1,$I16+2,$J16),OFFSET(latency!$A$1,$I16+7,$J16),OFFSET(latency!$A$1,$I16+8,$J16),OFFSET(latency!$A$1,$I16+9,$J16)) -> 325.7 | C16: =OFFSET(latency!$A$1,$I16+3,$J16) -> 61.8 | D16: =SUM(OFFSET(latency!$A$1,$I16+4,$J16),OFFSET(latency!$A$1,$I16+5,$J16),OFFSET(latency!$A$1,$I16+6,$J16)) -> 321.5 | E16: =OFFSET(latency!$A$1,$I16+10,$J16) -> 20 | F16: =SUM(B16:E16) -> 729 | G16: =OFFSET(latency!$A$1,$I16,$J16) -> 732.7 | I16: 1 | J16: 5
A17: 2KB | B17: =SUM(OFFSET(latency!$A$1,$I17+1,$J17),OFFSET(latency!$A$1,$I17+2,$J17),OFFSET(latency!$A$1,$I17+7,$J17),OFFSET(latency!$A$1,$I17+8,$J17),OFFSET(latency!$A$1,$I17+9,$J17)) -> 817.4 | C17: =OFFSET(latency!$A$1,$I17+3,$J17) -> 60.4 | D17: =SUM(OFFSET(latency!$A$1,$I17+4,$J17),OFFSET(latency!$A$1,$I17+5,$J17),OFFSET(latency!$A$1,$I17+6,$J17)) -> 299.1 | E17: =OFFSET(latency!$A$1,$I17+10,$J17) -> 19.9 | F17: =SUM(B17:E17) -> 1196.8 | G17: =OFFSET(latency!$A$1,$I17,$J17) -> 709 | I17: 12 | J17: 5
A18: 4KB | B18: =SUM(OFFSET(latency!$A$1,$I18+1,$J18),OFFSET(latency!$A$1,$I18+2,$J18),OFFSET(latency!$A$1,$I18+7,$J18),OFFSET(latency!$A$1,$I18+8,$J18),OFFSET(latency!$A$1,$I18+9,$J18)) -> 861.8 | C18: =OFFSET(latency!$A$1,$I18+3,$J18) -> 65.4 | D18: =SUM(OFFSET(latency!$A$1,$I18+4,$J18),OFFSET(latency!$A$1,$I18+5,$J18),OFFSET(latency!$A$1,$I18+6,$J18)) -> 330.8 | E18: =OFFSET(latency!$A$1,$I18+10,$J18) -> 20.5 | F18: =SUM(B18:E18) -> 1278.5 | G18: =OFFSET(latency!$A$1,$I18,$J18) -> 759.2 | I18: 23 | J18: 5
A19: 8KB | B19: =SUM(OFFSET(latency!$A$1,$I19+1,$J19),OFFSET(latency!$A$1,$I19+2,$J19),OFFSET(latency!$A$1,$I19+7,$J19),OFFSET(latency!$A$1,$I19+8,$J19),OFFSET(latency!$A$1,$I19+9,$J19)) -> 863.3 | C19: =OFFSET(latency!$A$1,$I19+3,$J19) -> 71.1 | D19: =SUM(OFFSET(latency!$A$1,$I19+4,$J19),OFFSET(latency!$A$1,$I19+5,$J19),OFFSET(latency!$A$1,$I19+6,$J19)) -> 270 | E19: =OFFSET(latency!$A$1,$I19+10,$J19) -> 57.5 | F19: =SUM(B19:E19) -> 1261.9 | G19: =OFFSET(latency!$A$1,$I19,$J19) -> 756.6 | I19: 34 | J19: 5
A20: 16KB | B20: =SUM(OFFSET(latency!$A$1,$I20+1,$J20),OFFSET(latency!$A$1,$I20+2,$J20),OFFSET(latency!$A$1,$I20+7,$J20),OFFSET(latency!$A$1,$I20+8,$J20),OFFSET(latency!$A$1,$I20+9,$J20)) -> 1105.8 | C20: =OFFSET(latency!$A$1,$I20+3,$J20) -> 127.4 | D20: =SUM(OFFSET(latency!$A$1,$I20+4,$J20),OFFSET(latency!$A$1,$I20+5,$J20),OFFSET(latency!$A$1,$I20+6,$J20)) -> 362.7 | E20: =OFFSET(latency!$A$1,$I20+10,$J20) -> 88.4 | F20: =SUM(B20:E20) -> 1684.3 | G20: =OFFSET(latency!$A$1,$I20,$J20) -> 1004.5 | I20: 45 | J20: 5
A21: 32KB | B21: =SUM(OFFSET(latency!$A$1,$I21+1,$J21),OFFSET(latency!$A$1,$I21+2,$J21),OFFSET(latency!$A$1,$I21+7,$J21),OFFSET(latency!$A$1,$I21+8,$J21),OFFSET(latency!$A$1,$I21+9,$J21)) -> 1166.4 | C21: =OFFSET(latency!$A$1,$I21+3,$J21) -> 136.6 | D21: =SUM(OFFSET(latency!$A$1,$I21+4,$J21),OFFSET(latency!$A$1,$I21+5,$J21),OFFSET(latency!$A$1,$I21+6,$J21)) -> 356.6 | E21: =OFFSET(latency!$A$1,$I21+10,$J21) -> 118.7 | F21: =SUM(B21:E21) -> 1778.3 | G21: =OFFSET(latency!$A$1,$I21,$J21) -> 1098.6 | I21: 56 | J21: 5
A22: 64KB | B22: =SUM(OFFSET(latency!$A$1,$I22+1,$J22),OFFSET(latency!$A$1,$I22+2,$J22),OFFSET(latency!$A$1,$I22+7,$J22),OFFSET(latency!$A$1,$I22+8,$J22),OFFSET(latency!$A$1,$I22+9,$J22)) -> 1307.5 | C22: =OFFSET(latency!$A$1,$I22+3,$J22) -> 177.3 | D22: =SUM(OFFSET(latency!$A$1,$I22+4,$J22),OFFSET(latency!$A$1,$I22+5,$J22),OFFSET(latency!$A$1,$I22+6,$J22)) -> 507.5 | E22: =OFFSET(latency!$A$1,$I22+10,$J22) -> 178.3 | F22: =SUM(B22:E22) -> 2170.6 | G22: =OFFSET(latency!$A$1,$I22,$J22) -> 1391.6 | I22: 67 | J22: 5
A23: 128KB | B23: =SUM(OFFSET(latency!$A$1,$I23+1,$J23),OFFSET(latency!$A$1,$I23+2,$J23),OFFSET(latency!$A$1,$I23+7,$J23),OFFSET(latency!$A$1,$I23+8,$J23),OFFSET(latency!$A$1,$I23+9,$J23)) -> 1724.2 | C23: =OFFSET(latency!$A$1,$I23+3,$J23) -> 187.7 | D23: =SUM(OFFSET(latency!$A$1,$I23+4,$J23),OFFSET(latency!$A$1,$I23+5,$J23),OFFSET(latency!$A$1,$I23+6,$J23)) -> 715.6 | E23: =OFFSET(latency!$A$1,$I23+10,$J23) -> 259.4 | F23: =SUM(B23:E23) -> 2886.9 | G23: =OFFSET(latency!$A$1,$I23,$J23) -> 1897.7 | I23: 78 | J23: 5
A25: p99 (us)
A26: size_bytes | B26: RaftLeader | C26: Network | D26: FollowerReplication | E26: ApplySM | F26: Total (구간 합) | G26: Total (원본 측정) | I26: base(도우미) | J26: metric_col
A27: 1KB | B27: =SUM(OFFSET(latency!$A$1,$I27+1,$J27),OFFSET(latency!$A$1,$I27+2,$J27),OFFSET(latency!$A$1,$I27+7,$J27),OFFSET(latency!$A$1,$I27+8,$J27),OFFSET(latency!$A$1,$I27+9,$J27)) -> 660.1 | C27: =OFFSET(latency!$A$1,$I27+3,$J27) -> 199 | D27: =SUM(OFFSET(latency!$A$1,$I27+4,$J27),OFFSET(latency!$A$1,$I27+5,$J27),OFFSET(latency!$A$1,$I27+6,$J27)) -> 591.8 | E27: =OFFSET(latency!$A$1,$I27+10,$J27) -> 66.2 | F27: =SUM(B27:E27) -> 1517.1 | G27: =OFFSET(latency!$A$1,$I27,$J27) -> 1127.9 | I27: 1 | J27: 6
A28: 2KB | B28: =SUM(OFFSET(latency!$A$1,$I28+1,$J28),OFFSET(latency!$A$1,$I28+2,$J28),OFFSET(latency!$A$1,$I28+7,$J28),OFFSET(latency!$A$1,$I28+8,$J28),OFFSET(latency!$A$1,$I28+9,$J28)) -> 1435.7 | C28: =OFFSET(latency!$A$1,$I28+3,$J28) -> 196.9 | D28: =SUM(OFFSET(latency!$A$1,$I28+4,$J28),OFFSET(latency!$A$1,$I28+5,$J28),OFFSET(latency!$A$1,$I28+6,$J28)) -> 559.5 | E28: =OFFSET(latency!$A$1,$I28+10,$J28) -> 56.3 | F28: =SUM(B28:E28) -> 2248.4 | G28: =OFFSET(latency!$A$1,$I28,$J28) -> 1104 | I28: 12 | J28: 6
A29: 4KB | B29: =SUM(OFFSET(latency!$A$1,$I29+1,$J29),OFFSET(latency!$A$1,$I29+2,$J29),OFFSET(latency!$A$1,$I29+7,$J29),OFFSET(latency!$A$1,$I29+8,$J29),OFFSET(latency!$A$1,$I29+9,$J29)) -> 1469.4 | C29: =OFFSET(latency!$A$1,$I29+3,$J29) -> 206.2 | D29: =SUM(OFFSET(latency!$A$1,$I29+4,$J29),OFFSET(latency!$A$1,$I29+5,$J29),OFFSET(latency!$A$1,$I29+6,$J29)) -> 600.1 | E29: =OFFSET(latency!$A$1,$I29+10,$J29) -> 55.2 | F29: =SUM(B29:E29) -> 2330.9 | G29: =OFFSET(latency!$A$1,$I29,$J29) -> 1164.2 | I29: 23 | J29: 6
A30: 8KB | B30: =SUM(OFFSET(latency!$A$1,$I30+1,$J30),OFFSET(latency!$A$1,$I30+2,$J30),OFFSET(latency!$A$1,$I30+7,$J30),OFFSET(latency!$A$1,$I30+8,$J30),OFFSET(latency!$A$1,$I30+9,$J30)) -> 1432.2 | C30: =OFFSET(latency!$A$1,$I30+3,$J30) -> 209.6 | D30: =SUM(OFFSET(latency!$A$1,$I30+4,$J30),OFFSET(latency!$A$1,$I30+5,$J30),OFFSET(latency!$A$1,$I30+6,$J30)) -> 565.8 | E30: =OFFSET(latency!$A$1,$I30+10,$J30) -> 84.2 | F30: =SUM(B30:E30) -> 2291.8 | G30: =OFFSET(latency!$A$1,$I30,$J30) -> 1119.2 | I30: 34 | J30: 6
A31: 16KB | B31: =SUM(OFFSET(latency!$A$1,$I31+1,$J31),OFFSET(latency!$A$1,$I31+2,$J31),OFFSET(latency!$A$1,$I31+7,$J31),OFFSET(latency!$A$1,$I31+8,$J31),OFFSET(latency!$A$1,$I31+9,$J31)) -> 1614.1 | C31: =OFFSET(latency!$A$1,$I31+3,$J31) -> 200.6 | D31: =SUM(OFFSET(latency!$A$1,$I31+4,$J31),OFFSET(latency!$A$1,$I31+5,$J31),OFFSET(latency!$A$1,$I31+6,$J31)) -> 622.4 | E31: =OFFSET(latency!$A$1,$I31+10,$J31) -> 112.7 | F31: =SUM(B31:E31) -> 2549.8 | G31: =OFFSET(latency!$A$1,$I31,$J31) -> 1277.5 | I31: 45 | J31: 6
A32: 32KB | B32: =SUM(OFFSET(latency!$A$1,$I32+1,$J32),OFFSET(latency!$A$1,$I32+2,$J32),OFFSET(latency!$A$1,$I32+7,$J32),OFFSET(latency!$A$1,$I32+8,$J32),OFFSET(latency!$A$1,$I32+9,$J32)) -> 1830.4 | C32: =OFFSET(latency!$A$1,$I32+3,$J32) -> 210.2 | D32: =SUM(OFFSET(latency!$A$1,$I32+4,$J32),OFFSET(latency!$A$1,$I32+5,$J32),OFFSET(latency!$A$1,$I32+6,$J32)) -> 627.4 | E32: =OFFSET(latency!$A$1,$I32+10,$J32) -> 180.3 | F32: =SUM(B32:E32) -> 2848.3 | G32: =OFFSET(latency!$A$1,$I32,$J32) -> 1473.5 | I32: 56 | J32: 6
A33: 64KB | B33: =SUM(OFFSET(latency!$A$1,$I33+1,$J33),OFFSET(latency!$A$1,$I33+2,$J33),OFFSET(latency!$A$1,$I33+7,$J33),OFFSET(latency!$A$1,$I33+8,$J33),OFFSET(latency!$A$1,$I33+9,$J33)) -> 2114.5 | C33: =OFFSET(latency!$A$1,$I33+3,$J33) -> 214.5 | D33: =SUM(OFFSET(latency!$A$1,$I33+4,$J33),OFFSET(latency!$A$1,$I33+5,$J33),OFFSET(latency!$A$1,$I33+6,$J33)) -> 811.1 | E33: =OFFSET(latency!$A$1,$I33+10,$J33) -> 322.7 | F33: =SUM(B33:E33) -> 3462.8 | G33: =OFFSET(latency!$A$1,$I33,$J33) -> 1868.1 | I33: 67 | J33: 6
A34: 128KB | B34: =SUM(OFFSET(latency!$A$1,$I34+1,$J34),OFFSET(latency!$A$1,$I34+2,$J34),OFFSET(latency!$A$1,$I34+7,$J34),OFFSET(latency!$A$1,$I34+8,$J34),OFFSET(latency!$A$1,$I34+9,$J34)) -> 2584.9 | C34: =OFFSET(latency!$A$1,$I34+3,$J34) -> 230.5 | D34: =SUM(OFFSET(latency!$A$1,$I34+4,$J34),OFFSET(latency!$A$1,$I34+5,$J34),OFFSET(latency!$A$1,$I34+6,$J34)) -> 998.3 | E34: =OFFSET(latency!$A$1,$I34+10,$J34) -> 534.1 | F34: =SUM(B34:E34) -> 4347.8 | G34: =OFFSET(latency!$A$1,$I34,$J34) -> 2420.1 | I34: 78 | J34: 6
